Workbook
Name Slicer_Department: #N/A
Name Slicer_Education_Field2: #N/A
Name Slicer_Gender1: #N/A

Sheet KPI
A3: Count of Employee Number | B3: Average of Age | C3: Sum of CF_attrition count
A4: 1470 | B4: 36.92381 | C4: 237
A7: Total Employee | B7: Average Age | C7: Attrition Count | D7: Active employee | E7: Atrrition Rate
A8: =GETPIVOTDATA("Count of Employee Number",$A$3) -> 1470 | B8: =GETPIVOTDATA("Average of Age",$A$3) -> 36.92381 | C8: =GETPIVOTDATA("Sum of CF_attrition count",$A$3) -> 237 | D8: =A8-C8 -> 1233 | E8: =C8/A8 -> 0.16122449

Sheet Rating
A3: Average of Job Satisfaction
A4: 2.6265306
A7: Rating | B7: =GETPIVOTDATA("Job Satisfaction",$A$3) -> 2.6265306 | C7: =B7/4 -> 0.65663265
A8: Balance Rating | B8: =4-B7 -> 1.3734694 | C8: =B8/4 -> 0.34336735

Sheet Gender
A3: Row Labels | B3: Count of Employee Count
A4: Female | B4: 588
A5: Male | B5: 882
A6: Grand Total | B6: 1470
A9: Female | B9: =IFERROR(GETPIVOTDATA("Employee Count",$A$3,"Gender","Female"),0) -> 588 | C9: =IFERROR(B9/($B$9+$B$10),0) -> 0.4
A10: Male | B10: =IFERROR(GETPIVOTDATA("Employee Count",$A$3,"Gender","Male"),0) -> 882 | C10: =IFERROR(B10/($B$10+$B$9),0) -> 0.6

Sheet EducationByAttrition
A3: Education | B3: Sum of CF_attrition count
A4: Doctoral Degree | B4: 5
A5: High School | B5: 31
A6: Associates Degree | B6: 44
A7: Master's Degree | B7: 58
A8: Bachelor's Degree | B8: 99
A9: Grand Total | B9: 237

Sheet AttritionByJob
A3: Job Role | B3: Sum of CF_attrition count | D3: Job Role | E3: Attrition
A4: Healthcare Representative | B4: 9 | D4: =A4 -> Healthcare Representative | E4: =GETPIVOTDATA("CF_attrition count",$A$3,"Job Role",A4) -> 9
A5: Human Resources | B5: 12 | D5: =A5 -> Human Resources | E5: =GETPIVOTDATA("CF_attrition count",$A$3,"Job Role",A5) -> 12
A6: Laboratory Technician | B6: 62 | D6: =A6 -> Laboratory Technician | E6: =GETPIVOTDATA("CF_attrition count",$A$3,"Job Role",A6) -> 62
A7: Manager | B7: 5 | D7: =A7 -> Manager | E7: =GETPIVOTDATA("CF_attrition count",$A$3,"Job Role",A7) -> 5
A8: Manufacturing Director | B8: 10 | D8: =A8 -> Manufacturing Director | E8: =GETPIVOTDATA("CF_attrition count",$A$3,"Job Role",A8) -> 10
A9: Research Director | B9: 2 | D9: =A9 -> Research Director | E9: =GETPIVOTDATA("CF_attrition count",$A$3,"Job Role",A9) -> 2
A10: Research Scientist | B10: 47 | D10: =A10 -> Research Scientist | E10: =GETPIVOTDATA("CF_attrition count",$A$3,"Job Role",A10) -> 47
A11: Sales Executive | B11: 57 | D11: =A11 -> Sales Executive | E11: =GETPIVOTDATA("CF_attrition count",$A$3,"Job Role",A11) -> 57
A12: Sales Representative | B12: 33 | D12: =A12 -> Sales Representative | E12: =GETPIVOTDATA("CF_attrition count",$A$3,"Job Role",A12) -> 33
A13: Grand Total | B13: 237

Sheet DepartmentWiseAttrition
A3: Department | B3: Sum of CF_attrition count
A4: HR | B4: 0.050632911
A5: R&D | B5: 0.56118143
A6: Sales | B6: 0.38818565
A7: Grand Total | B7: 1

Sheet AttritionByAgeGroup
A3: CF_age band | B3: Sum of CF_attrition count
A4: 25 - 34 | B4: 112
A5: 35 - 44 | B5: 51
A6: Under 25 | B6: 38
A7: 45 - 54 | B7: 25
A8: Over 55 | B8: 11
A9: Grand Total | B9: 237

Sheet AttritionByMaritalStatus
A3: Marital Status | B3: Count of Attrition | D3: Marital Status | E3: Atrrition
A4: Divorced | B4: 327 | D4: =A4 -> Divorced | E4: =GETPIVOTDATA("Attrition",$A$3,"Marital Status",A4) -> 327
A5: Single | B5: 470 | D5: =A5 -> Single | E5: =GETPIVOTDATA("Attrition",$A$3,"Marital Status",A5) -> 470
A6: Married | B6: 673 | D6: =A6 -> Married | E6: =GETPIVOTDATA("Attrition",$A$3,"Marital Status",A6) -> 673
A7: Grand Total | B7: 1470

Sheet Data
A1: Attrition | B1: Business Travel | C1: CF_age band | D1: CF_attrition label | E1: Department | F1: Education Field | G1: emp no | H1: Employee Number | I1: Gender | J1: Job Role | K1: Marital Status | L1: Over Time | M1: Over18 | N1: Training Times Last Year | O1: -2 | P1: 0 | Q1: Age | R1: CF_attrition count | S1: CF_attrition counts | T1: CF_attrition rate | U1: CF_current Employee | V1: Daily Rate | W1: Distance From Home | X1: Education | Y1: Employee Count | Z1: Environment Satisfaction | AA1: Hourly Rate | AB1: Job Involvement | AC1: Job Level | AD1: Job Satisfaction | AE1: Monthly Income | AF1: Monthly Rate | AG1: Num Companies Worked | AH1: Percent Salary Hike | AI1: Performance Rating | AJ1: Relationship Satisfaction | AK1: Standard Hours | AL1: Stock Option Level | AM1: Total Working Years | AN1: Work Life Balance | AO1: Years At Company | AP1: Years In Current Role | AQ1: Years Since Last Promotion | AR1: Years With Curr Manager
A2: Yes | B2: Travel_Rarely | C2: 35 - 44 | D2: Ex-Employees | E2: Sales | F2: Life Sciences | G2: STAFF-1 | H2: 1 | I2: Female | J2: Sales Executive | K2: Single | L2: Yes | M2: Y | N2: 0 | O2: -2 | P2: 0 | Q2: 41 | R2: 1 | S2: 1 | T2: 1 | U2: 0 | V2: 1102 | W2: 1 | X2: Associates Degree | Y2: 1 | Z2: 2 | AA2: 94 | AB2: 3 | AC2: 2 | AD2: 4 | AE2: 5993 | AF2: 19479 | AG2: 8 | AH2: 11 | AI2: 3 | AJ2: 1 | AK2: 80 | AL2: 0 | AM2: 8 | AN2: 1 | AO2: 6 | AP2: 4 | AQ2: 0 | AR2: 5
A3: No | B3: Travel_Frequently | C3: 45 - 54 | D3: Current Employees | E3: R&D | F3: Life Sciences | G3: STAFF-2 | H3: 2 | I3: Male | J3: Research Scientist | K3: Married | L3: No | M3: Y | N3: 3 | O3: -2 | P3: 0 | Q3: 49 | R3: 0 | T3: 0 | U3: 1 | V3: 279 | W3: 8 | X3: High School | Y3: 1 | Z3: 3 | AA3: 61 | AB3: 2 | AC3: 2 | AD3: 2 | AE3: 5130 | AF3: 24907 | AG3: 1 | AH3: 23 | AI3: 4 | AJ3: 4 | AK3: 80 | AL3: 1 | AM3: 10 | AN3: 3 | AO3: 10 | AP3: 7 | AQ3: 1 | AR3: 7
A4: Yes | B4: Travel_Rarely | C4: 35 - 44 | D4: Ex-Employees | E4: R&D | F4: Other | G4: STAFF-4 | H4: 4 | I4: Male | J4: Laboratory Technician | K4: Single | L4: Yes | M4: Y | N4: 3 | O4: -2 | P4: 0 | Q4: 37 | R4: 1 | S4: 1 | T4: 1 | U4: 0 | V4: 1373 | W4: 2 | X4: Associates Degree | Y4: 1 | Z4: 4 | AA4: 92 | AB4: 2 | AC4: 1 | AD4: 3 | AE4: 2090 | AF4: 2396 | AG4: 6 | AH4: 15 | AI4: 3 | AJ4: 2 | AK4: 80 | AL4: 0 | AM4: 7 | AN4: 3 | AO4: 0 | AP4: 0 | AQ4: 0 | AR4: 0
A5: No | B5: Travel_Frequently | C5: 25 - 34 | D5: Current Employees | E5: R&D | F5: Life Sciences | G5: STAFF-5 | H5: 5 | I5: Female | J5: Research Scientist | K5: Married | L5: Yes | M5: Y | N5: 3 | O5: -2 | P5: 0 | Q5: 33 | R5: 0 | T5: 0 | U5: 1 | V5: 1392 | W5: 3 | X5: Master's Degree | Y5: 1 | Z5: 4 | AA5: 56 | AB5: 3 | AC5: 1 | AD5: 3 | AE5: 2909 | AF5: 23159 | AG5: 1 | AH5: 11 | AI5: 3 | AJ5: 3 | AK5: 80 | AL5: 0 | AM5: 8 | AN5: 3 | AO5: 8 | AP5: 7 | AQ5: 3 | AR5: 0
A6: No | B6: Travel_Rarely | C6: 25 - 34 | D6: Current Employees | E6: R&D | F6: Medical | G6: STAFF-7 | H6: 7 | I6: Male | J6: Laboratory Technician | K6: Married | L6: No | M6: Y | N6: 3 | O6: -2 | P6: 0 | Q6: 27 | R6: 0 | T6: 0 | U6: 1 | V6: 591 | W6: 2 | X6: High School | Y6: 1 | Z6: 1 | AA6: 40 | AB6: 3 | AC6: 1 | AD6: 2 | AE6: 3468 | AF6: 16632 | AG6: 9 | AH6: 12 | AI6: 3 | AJ6: 4 | AK6: 80 | AL6: 1 | AM6: 6 | AN6: 3 | AO6: 2 | AP6: 2 | AQ6: 2 | AR6: 2
A7: No | B7: Travel_Frequently | C7: 25 - 34 | D7: Current Employees | E7: R&D | F7: Life Sciences | G7: STAFF-8 | H7: 8 | I7: Male | J7: Laboratory Technician | K7: Single | L7: No | M7: Y | N7: 2 | O7: -2 | P7: 0 | Q7: 32 | R7: 0 | T7: 0 | U7: 1 | V7: 1005 | W7: 2 | X7: Associates Degree | Y7: 1 | Z7: 4 | AA7: 79 | AB7: 3 | AC7: 1 | AD7: 2 | AE7: 3068 | AF7: 11864 | AG7: 0 | AH7: 13 | AI7: 3 | AJ7: 3 | AK7: 80 | AL7: 0 | AM7: 8 | AN7: 2 | AO7: 7 | AP7: 7 | AQ7: 3 | AR7: 6
A8: No | B8: Travel_Rarely | C8: Over 55 | D8: Current Employees | E8: R&D | F8: Medical | G8: STAFF-10 | H8: 10 | I8: Female | J8: Laboratory Technician | K8: Married | L8: Yes | M8: Y | N8: 3 | O8: -2 | P8: 0 | Q8: 59 | R8: 0 | T8: 0 | U8: 1 | V8: 1324 | W8: 3 | X8: Bachelor's Degree | Y8: 1 | Z8: 3 | AA8: 81 | AB8: 4 | AC8: 1 | AD8: 4 | AE8: 2670 | AF8: 9964 | AG8: 4 | AH8: 20 | AI8: 4 | AJ8: 1 | AK8: 80 | AL8: 3 | AM8: 12 | AN8: 2 | AO8: 1 | AP8: 0 | AQ8: 0 | AR8: 0
A9: No | B9: Travel_Rarely | C9: 25 - 34 | D9: Current Employees | E9: R&D | F9: Life Sciences | G9: STAFF-11 | H9: 11 | I9: Male | J9: Laboratory Technician | K9: Divorced | L9: No | M9: Y | N9: 2 | O9: -2 | P9: 0 | Q9: 30 | R9: 0 | T9: 0 | U9: 1 | V9: 1358 | W9: 24 | X9: High School | Y9: 1 | Z9: 4 | AA9: 67 | AB9: 3 | AC9: 1 | AD9: 2 | AE9: 2693 | AF9: 13335 | AG9: 1 | AH9: 22 | AI9: 4 | AJ9: 2 | AK9: 80 | AL9: 1 | AM9: 1 | AN9: 3 | AO9: 1 | AP9: 0 | AQ9: 0 | AR9: 0
A10: No | B10: Travel_Frequently | C10: 35 - 44 | D10: Current Employees | E10: R&D | F10: Life Sciences | G10: STAFF-12 | H10: 12 | I10: Male | J10: Manufacturing Director | K10: Single | L10: No | M10: Y | N10: 2 | O10: -2 | P10: 0 | Q10: 38 | R10: 0 | T10: 0 | U10: 1 | V10: 216 | W10: 23 | X10: Bachelor's Degree | Y10: 1 | Z10: 4 | AA10: 44 | AB10: 2 | AC10: 3 | AD10: 2 | AE10: 9526 | AF10: 8787 | AG10: 0 | AH10: 21 | AI10: 4 | AJ10: 2 | AK10: 80 | AL10: 0 | AM10: 10 | AN10: 3 | AO10: 9 | AP10: 7 | AQ10: 1 | AR10: 8
A11: No | B11: Travel_Rarely | C11: 35 - 44 | D11: Current Employees | E11: R&D | F11: Medical | G11: STAFF-13 | H11: 13 | I11: Male | J11: Healthcare Representative | K11: Married | L11: No | M11: Y | N11: 3 | O11: -2 | P11: 0 | Q11: 36 | R11: 0 | T11: 0 | U11: 1 | V11: 1299 | W11: 27 | X11: Bachelor's Degree | Y11: 1 | Z11: 3 | AA11: 94 | AB11: 3 | AC11: 2 | AD11: 3 | AE11: 5237 | AF11: 16577 | AG11: 6 | AH11: 13 | AI11: 3 | AJ11: 2 | AK11: 80 | AL11: 2 | AM11: 17 | AN11: 2 | AO11: 7 | AP11: 7 | AQ11: 7 | AR11: 7
A12: No | B12: Travel_Rarely | C12: 35 - 44 | D12: Current Employees | E12: R&D | F12: Medical | G12: STAFF-14 | H12: 14 | I12: Male | J12: Laboratory Technician | K12: Married | L12: No | M12: Y | N12: 5 | O12: -2 | P12: 0 | Q12: 35 | R12: 0 | T12: 0 | U12: 1 | V12: 809 | W12: 16 | X12: Bachelor's Degree | Y12: 1 | Z12: 1 | AA12: 84 | AB12: 4 | AC12: 1 | AD12: 2 | AE12: 2426 | AF12: 16479 | AG12: 0 | AH12: 13 | AI12: 3 | AJ12: 3 | AK12: 80 | AL12: 1 | AM12: 6 | AN12: 3 | AO12: 5 | AP12: 4 | AQ12: 0 | AR12: 3
A13: No | B13: Travel_Rarely | C13: 25 - 34 | D13: Current Employees | E13: R&D | F13: Life Sciences | G13: STAFF-15 | H13: 15 | I13: Female | J13: Laboratory Technician | K13: Single | L13: Yes | M13: Y | N13: 3 | O13: -2 | P13: 0 | Q13: 29 | R13: 0 | T13: 0 | U13: 1 | V13: 153 | W13: 15 | X13: Associates Degree | Y13: 1 | Z13: 4 | AA13: 49 | AB13: 2 | AC13: 2 | AD13: 2 | AE13: 4193 | AF13: 12682 | AG13: 0 | AH13: 12 | AI13: 3 | AJ13: 4 | AK13: 80 | AL13: 0 | AM13: 10 | AN13: 3 | AO13: 9 | AP13: 5 | AQ13: 0 | AR13: 8
A14: No | B14: Travel_Rarely | C14: 25 - 34 | D14: Current Employees | E14: R&D | F14: Life Sciences | G14: STAFF-16 | H14: 16 | I14: Male | J14: Research Scientist | K14: Divorced | L14: No | M14: Y | N14: 1 | O14: -2 | P14: 0 | Q14: 31 | R14: 0 | T14: 0 | U14: 1 | V14: 670 | W14: 26 | X14: High School | Y14: 1 | Z14: 1 | AA14: 31 | AB14: 3 | AC14: 1 | AD14: 2 | AE14: 2911 | AF14: 15170 | AG14: 1 | AH14: 17 | AI14: 3 | AJ14: 4 | AK14: 80 | AL14: 1 | AM14: 5 | AN14: 2 | AO14: 5 | AP14: 2 | AQ14: 4 | AR14: 3
A15: No | B15: Travel_Rarely | C15: 25 - 34 | D15: Current Employees | E15: R&D | F15: Medical | G15: STAFF-18 | H15: 18 | I15: Male | J15: Laboratory Technician | K15: Divorced | L15: No | M15: Y | N15: 2 | O15: -2 | P15: 0 | Q15: 34 | R15: 0 | T15: 0 | U15: 1 | V15: 1346 | W15: 19 | X15: Associates Degree | Y15: 1 | Z15: 2 | AA15: 93 | AB15: 3 | AC15: 1 | AD15: 4 | AE15: 2661 | AF15: 8758 | AG15: 0 | AH15: 11 | AI15: 3 | AJ15: 3 | AK15: 80 | AL15: 1 | AM15: 3 | AN15: 3 | AO15: 2 | AP15: 2 | AQ15: 1 | AR15: 2
A16: Yes | B16: Travel_Rarely | C16: 25 - 34 | D16: Ex-Employees | E16: R&D | F16: Life Sciences | G16: STAFF-19 | H16: 19 | I16: Male | J16: Laboratory Technician | K16: Single | L16: Yes | M16: Y | N16: 4 | O16: -2 | P16: 0 | Q16: 28 | R16: 1 | S16: 1 | T16: 1 | U16: 0 | V16: 103 | W16: 24 | X16: Bachelor's Degree | Y16: 1 | Z16: 3 | AA16: 50 | AB16: 2 | AC16: 1 | AD16: 2 | AE16: 2028 | AF16: 12947 | AG16: 5 | AH16: 14 | AI16: 3 | AJ16: 2 | AK16: 80 | AL16: 0 | AM16: 6 | AN16: 3 | AO16: 4 | AP16: 2 | AQ16: 0 | AR16: 3
A17: No | B17: Travel_Rarely | C17: 25 - 34 | D17: Current Employees | E17: R&D | F17: Life Sciences | G17: STAFF-20 | H17: 20 | I17: Female | J17: Manufacturing Director | K17: Divorced | L17: No | M17: Y | N17: 1 | O17: -2 | P17: 0 | Q17: 29 | R17: 0 | T17: 0 | U17: 1 | V17: 1389 | W17: 21 | X17: Master's Degree | Y17: 1 | Z17: 2 | AA17: 51 | AB17: 4 | AC17: 3 | AD17: 2 | AE17: 9980 | AF17: 10195 | AG17: 1 | AH17: 11 | AI17: 3 | AJ17: 3 | AK17: 80 | AL17: 1 | AM17: 10 | AN17: 3 | AO17: 10 | AP17: 9 | AQ17: 8 | AR17: 8
A18: No | B18: Travel_Rarely | C18: 25 - 34 | D18: Current Employees | E18: R&D | F18: Life Sciences | G18: STAFF-21 | H18: 21 | I18: Male | J18: Research Scientist | K18: Divorced | L18: Yes | M18: Y | N18: 5 | O18: -2 | P18: 0 | Q18: 32 | R18: 0 | T18: 0 | U18: 1 | V18: 334 | W18: 5 | X18: Associates Degree | Y18: 1 | Z18: 1 | AA18: 80 | AB18: 4 | AC18: 1 | AD18: 2 | AE18: 3298 | AF18: 15053 | AG18: 0 | AH18: 12 | AI18: 3 | AJ18: 4 | AK18: 80 | AL18: 2 | AM18: 7 | AN18: 2 | AO18: 6 | AP18: 2 | AQ18: 0 | AR18: 5
A19: No | B19: Non-Travel | C19: Under 25 | D19: Current Employees | E19: R&D | F19: Medical | G19: STAFF-22 | H19: 22 | I19: Male | J19: Laboratory Technician | K19: Divorced | L19: Yes | M19: Y | N19: 2 | O19: -2 | P19: 0 | Q19: 22 | R19: 0 | T19: 0 | U19: 1 | V19: 1123 | W19: 16 | X19: Associates Degree | Y19: 1 | Z19: 4 | AA19: 96 | AB19: 4 | AC19: 1 | AD19: 4 | AE19: 2935 | AF19: 7324 | AG19: 1 | AH19: 13 | AI19: 3 | AJ19: 2 | AK19: 80 | AL19: 2 | AM19: 1 | AN19: 2 | AO19: 1 | AP19: 0 | AQ19: 0 | AR19: 0
A20: No | B20: Travel_Rarely | C20: 45 - 54 | D20: Current Employees | E20: Sales | F20: Life Sciences | G20: STAFF-23 | H20: 23 | I20: Female | J20: Manager | K20: Married | L20: No | M20: Y | N20: 3 | O20: -2 | P20: 0 | Q20: 53 | R20: 0 | T20: 0 | U20: 1 | V20: 1219 | W20: 2 | X20: Master's Degree | Y20: 1 | Z20: 1 | AA20: 78 | AB20: 2 | AC20: 4 | AD20: 2 | AE20: 15427 | AF20: 22021 | AG20: 2 | AH20: 16 | AI20: 3 | AJ20: 3 | AK20: 80 | AL20: 0 | AM20: 31 | AN20: 3 | AO20: 25 | AP20: 8 | AQ20: 3 | AR20: 7
A21: No | B21: Travel_Rarely | C21: 35 - 44 | D21: Current Employees | E21: R&D | F21: Life Sciences | G21: STAFF-24 | H21: 24 | I21: Male | J21: Research Scientist | K21: Single | L21: Yes | M21: Y | N21: 3 | O21: -2 | P21: 0 | Q21: 38 | R21: 0 | T21: 0 | U21: 1 | V21: 371 | W21: 2 | X21: Bachelor's Degree | Y21: 1 | Z21: 4 | AA21: 45 | AB21: 3 | AC21: 1 | AD21: 2 | AE21: 3944 | AF21: 4306 | AG21: 5 | AH21: 11 | AI21: 3 | AJ21: 3 | AK21: 80 | AL21: 0 | AM21: 6 | AN21: 3 | AO21: 3 | AP21: 2 | AQ21: 1 | AR21: 2
A22: No | B22: Non-Travel | C22: Under 25 | D22: Current Employees | E22: R&D | F22: Other | G22: STAFF-26 | H22: 26 | I22: Female | J22: Manufacturing Director | K22: Divorced | L22: No | M22: Y | N22: 5 | O22: -2 | P22: 0 | Q22: 24 | R22: 0 | T22: 0 | U22: 1 | V22: 673 | W22: 11 | X22: Associates Degree | Y22: 1 | Z22: 1 | AA22: 96 | AB22: 4 | AC22: 2 | AD22: 3 | AE22: 4011 | AF22: 8232 | AG22: 0 | AH22: 18 | AI22: 3 | AJ22: 4 | AK22: 80 | AL22: 1 | AM22: 5 | AN22: 2 | AO22: 4 | AP22: 2 | AQ22: 1 | AR22: 3
A23: Yes | B23: Travel_Rarely | C23: 35 - 44 | D23: Ex-Employees | E23: Sales | F23: Life Sciences | G23: STAFF-27 | H23: 27 | I23: Male | J23: Sales Representative | K23: Single | L23: No | M23: Y | N23: 4 | O23: -2 | P23: 0 | Q23: 36 | R23: 1 | S23: 1 | T23: 1 | U23: 0 | V23: 1218 | W23: 9 | X23: Master's Degree | Y23: 1 | Z23: 3 | AA23: 82 | AB23: 2 | AC23: 1 | AD23: 2 | AE23: 3407 | AF23: 6986 | AG23: 7 | AH23: 23 | AI23: 4 | AJ23: 2 | AK23: 80 | AL23: 0 | AM23: 10 | AN23: 3 | AO23: 5 | AP23: 3 | AQ23: 0 | AR23: 3
A24: No | B24: Travel_Rarely | C24: 25 - 34 | D24: Current Employees | E24: R&D | F24: Life Sciences | G24: STAFF-28 | H24: 28 | I24: Female | J24: Research Director | K24: Single | L24: No | M24: Y | N24: 4 | O24: -2 | P24: 0 | Q24: 34 | R24: 0 | T24: 0 | U24: 1 | V24: 419 | W24: 7 | X24: Master's Degree | Y24: 1 | Z24: 1 | AA24: 53 | AB24: 3 | AC24: 3 | AD24: 2 | AE24: 11994 | AF24: 21293 | AG24: 0 | AH24: 11 | AI24: 3 | AJ24: 3 | AK24: 80 | AL24: 0 | AM24: 13 | AN24: 3 | AO24: 12 | AP24: 6 | AQ24: 2 | AR24: 11
A25: No | B25: Travel_Rarely | C25: Under 25 | D25: Current Employees | E25: R&D | F25: Life Sciences | G25: STAFF-30 | H25: 30 | I25: Male | J25: Research Scientist | K25: Single | L25: No | M25: Y | N25: 6 | O25: -2 | P25: 0 | Q25: 21 | R25: 0 | T25: 0 | U25: 1 | V25: 391 | W25: 15 | X25: Associates Degree | Y25: 1 | Z25: 3 | AA25: 96 | AB25: 3 | AC25: 1 | AD25: 2 | AE25: 1232 | AF25: 19281 | AG25: 1 | AH25: 14 | AI25: 3 | AJ25: 4 | AK25: 80 | AL25: 0 | AM25: 0 | AN25: 3 | AO25: 0 | AP25: 0 | AQ25: 0 | AR25: 0
A26: Yes | B26: Travel_Rarely | C26: 25 - 34 | D26: Ex-Employees | E26: R&D | F26: Medical | G26: STAFF-31 | H26: 31 | I26: Male | J26: Research Scientist | K26: Single | L26: No | M26: Y | N26: 2 | O26: -2 | P26: 0 | Q26: 34 | R26: 1 | S26: 1 | T26: 1 | U26: 0 | V26: 699 | W26: 6 | X26: High School | Y26: 1 | Z26: 2 | AA26: 83 | AB26: 3 | AC26: 1 | AD26: 4 | AE26: 2960 | AF26: 17102 | AG26: 2 | AH26: 11 | AI26: 3 | AJ26: 3 | AK26: 80 | AL26: 0 | AM26: 8 | AN26: 3 | AO26: 4 | AP26: 2 | AQ26: 1 | AR26: 3
A27: No | B27: Travel_Rarely | C27: 45 - 54 | D27: Current Employees | E27: R&D | F27: Other | G27: STAFF-32 | H27: 32 | I27: Female | J27: Manager | K27: Divorced | L27: No | M27: Y | N27: 3 | O27: -2 | P27: 0 | Q27: 53 | R27: 0 | T27: 0 | U27: 1 | V27: 1282 | W27: 5 | X27: Bachelor's Degree | Y27: 1 | Z27: 3 | AA27: 58 | AB27: 3 | AC27: 5 | AD27: 3 | AE27: 19094 | AF27: 10735 | AG27: 4 | AH27: 11 | AI27: 3 | AJ27: 4 | AK27: 80 | AL27: 1 | AM27: 26 | AN27: 2 | AO27: 14 | AP27: 13 | AQ27: 4 | AR27: 8
A28: Yes | B28: Travel_Frequently | C28: 25 - 34 | D28: Ex-Employees | E28: R&D | F28: Life Sciences | G28: STAFF-33 | H28: 33 | I28: Female | J28: Research Scientist | K28: Single | L28: Yes | M28: Y | N28: 5 | O28: -2 | P28: 0 | Q28: 32 | R28: 1 | S28: 1 | T28: 1 | U28: 0 | V28: 1125 | W28: 16 | X28: High School | Y28: 1 | Z28: 2 | AA28: 72 | AB28: 1 | AC28: 1 | AD28: 2 | AE28: 3919 | AF28: 4681 | AG28: 1 | AH28: 22 | AI28: 4 | AJ28: 2 | AK28: 80 | AL28: 0 | AM28: 10 | AN28: 3 | AO28: 10 | AP28: 2 | AQ28: 6 | AR28: 7
A29: No | B29: Travel_Rarely | C29: 35 - 44 | D29: Current Employees | E29: Sales | F29: Marketing | G29: STAFF-35 | H29: 35 | I29: Male | J29: Sales Executive | K29: Married | L29: No | M29: Y | N29: 2 | O29: -2 | P29: 0 | Q29: 42 | R29: 0 | T29: 0 | U29: 1 | V29: 691 | W29: 8 | X29: Master's Degree | Y29: 1 | Z29: 3 | AA29: 48 | AB29: 3 | AC29: 2 | AD29: 3 | AE29: 6825 | AF29: 21173 | AG29: 0 | AH29: 11 | AI29: 3 | AJ29: 4 | AK29: 80 | AL29: 1 | AM29: 10 | AN29: 3 | AO29: 9 | AP29: 7 | AQ29: 4 | AR29: 2
A30: No | B30: Travel_Rarely | C30: 35 - 44 | D30: Current Employees | E30: R&D | F30: Medical | G30: STAFF-36 | H30: 36 | I30: Female | J30: Healthcare Representative | K30: Married | L30: No | M30: Y | N30: 4 | O30: -2 | P30: 0 | Q30: 44 | R30: 0 | T30: 0 | U30: 1 | V30: 477 | W30: 7 | X30: Master's Degree | Y30: 1 | Z30: 1 | AA30: 42 | AB30: 2 | AC30: 3 | AD30: 4 | AE30: 10248 | AF30: 2094 | AG30: 3 | AH30: 14 | AI30: 3 | AJ30: 4 | AK30: 80 | AL30: 1 | AM30: 24 | AN30: 3 | AO30: 22 | AP30: 6 | AQ30: 5 | AR30: 17
A31: No | B31: Travel_Rarely | C31: 45 - 54 | D31: Current Employees | E31: Sales | F31: Marketing | G31: STAFF-38 | H31: 38 | I31: Female | J31: Manager | K31: Single | L31: No | M31: Y | N31: 2 | O31: -2 | P31: 0 | Q31: 46 | R31: 0 | T31: 0 | U31: 1 | V31: 705 | W31: 2 | X31: Master's Degree | Y31: 1 | Z31: 2 | AA31: 83 | AB31: 3 | AC31: 5 | AD31: 4 | AE31: 18947 | AF31: 22822 | AG31: 3 | AH31: 12 | AI31: 3 | AJ31: 4 | AK31: 80 | AL31: 0 | AM31: 22 | AN31: 2 | AO31: 2 | AP31: 2 | AQ31: 2 | AR31: 1
A32: No | B32: Travel_Rarely | C32: 25 - 34 | D32: Current Employees | E32: R&D | F32: Medical | G32: STAFF-39 | H32: 39 | I32: Male | J32: Laboratory Technician | K32: Single | L32: No | M32: Y | N32: 3 | O32: -2 | P32: 0 | Q32: 33 | R32: 0 | T32: 0 | U32: 1 | V32: 924 | W32: 2 | X32: Bachelor's Degree | Y32: 1 | Z32: 3 | AA32: 78 | AB32: 3 | AC32: 1 | AD32: 4 | AE32: 2496 | AF32: 6670 | AG32: 4 | AH32: 11 | AI32: 3 | AJ32: 4 | AK32: 80 | AL32: 0 | AM32: 7 | AN32: 3 | AO32: 1 | AP32: 1 | AQ32: 0 | AR32: 0
A33: No | B33: Travel_Rarely | C33: 35 - 44 | D33: Current Employees | E33: R&D | F33: Other | G33: STAFF-40 | H33: 40 | I33: Male | J33: Healthcare Representative | K33: Married | L33: Yes | M33: Y | N33: 5 | O33: -2 | P33: 0 | Q33: 44 | R33: 0 | T33: 0 | U33: 1 | V33: 1459 | W33: 10 | X33: Master's Degree | Y33: 1 | Z33: 4 | AA33: 41 | AB33: 3 | AC33: 2 | AD33: 4 | AE33: 6465 | AF33: 19121 | AG33: 2 | AH33: 13 | AI33: 3 | AJ33: 4 | AK33: 80 | AL33: 0 | AM33: 9 | AN33: 4 | AO33: 4 | AP33: 2 | AQ33: 1 | AR33: 3
A34: No | B34: Travel_Rarely | C34: 25 - 34 | D34: Current Employees | E34: R&D | F34: Medical | G34: STAFF-41 | H34: 41 | I34: Male | J34: Laboratory Technician | K34: Single | L34: No | M34: Y | N34: 5 | O34: -2 | P34: 0 | Q34: 30 | R34: 0 | T34: 0 | U34: 1 | V34: 125 | W34: 9 | X34: Associates Degree | Y34: 1 | Z34: 4 | AA34: 83 | AB34: 2 | AC34: 1 | AD34: 3 | AE34: 2206 | AF34: 16117 | AG34: 1 | AH34: 13 | AI34: 3 | AJ34: 1 | AK34: 80 | AL34: 0 | AM34: 10 | AN34: 3 | AO34: 10 | AP34: 0 | AQ34: 1 | AR34: 8
A35: Yes | B35: Travel_Rarely | C35: 35 - 44 | D35: Ex-Employees | E35: Sales | F35: Technical Degree | G35: STAFF-42 | H35: 42 | I35: Male | J35: Sales Representative | K35: Married | L35: No | M35: Y | N35: 6 | O35: -2 | P35: 0 | Q35: 39 | R35: 1 | S35: 1 | T35: 1 | U35: 0 | V35: 895 | W35: 5 | X35: Bachelor's Degree | Y35: 1 | Z35: 4 | AA35: 56 | AB35: 3 | AC35: 2 | AD35: 4 | AE35: 2086 | AF35: 3335 | AG35: 3 | AH35: 14 | AI35: 3 | AJ35: 3 | AK35: 80 | AL35: 1 | AM35: 19 | AN35: 4 | AO35: 1 | AP35: 0 | AQ35: 0 | AR35: 0
A36: Yes | B36: Travel_Rarely | C36: Under 25 | D36: Ex-Employees | E36: R&D | F36: Medical | G36: STAFF-45 | H36: 45 | I36: Male | J36: Research Scientist | K36: Married | L36: Yes | M36: Y | N36: 2 | O36: -2 | P36: 0 | Q36: 24 | R36: 1 | S36: 1 | T36: 1 | U36: 0 | V36: 813 | W36: 1 | X36: Bachelor's Degree | Y36: 1 | Z36: 2 | AA36: 61 | AB36: 3 | AC36: 1 | AD36: 4 | AE36: 2293 | AF36: 3020 | AG36: 2 | AH36: 16 | AI36: 3 | AJ36: 1 | AK36: 80 | AL36: 1 | AM36: 6 | AN36: 2 | AO36: 2 | AP36: 0 | AQ36: 2 | AR36: 0
A37: No | B37: Travel_Rarely | C37: 35 - 44 | D37: Current Employees | E37: R&D | F37: Medical | G37: STAFF-46 | H37: 46 | I37: Female | J37: Research Scientist | K37: Divorced | L37: No | M37: Y | N37: 3 | O37: -2 | P37: 0 | Q37: 43 | R37: 0 | T37: 0 | U37: 1 | V37: 1273 | W37: 2 | X37: Associates Degree | Y37: 1 | Z37: 4 | AA37: 72 | AB37: 4 | AC37: 1 | AD37: 3 | AE37: 2645 | AF37: 21923 | AG37: 1 | AH37: 12 | AI37: 3 | AJ37: 4 | AK37: 80 | AL37: 2 | AM37: 6 | AN37: 2 | AO37: 5 | AP37: 3 | AQ37: 1 | AR37: 4
A38: Yes | B38: Travel_Rarely | C38: 45 - 54 | D38: Ex-Employees | E38: Sales | F38: Marketing | G38: STAFF-47 | H38: 47 | I38: Male | J38: Sales Representative | K38: Married | L38: Yes | M38: Y | N38: 2 | O38: -2 | P38: 0 | Q38: 50 | R38: 1 | S38: 1 | T38: 1 | U38: 0 | V38: 869 | W38: 3 | X38: Associates Degree | Y38: 1 | Z38: 1 | AA38: 86 | AB38: 2 | AC38: 1 | AD38: 3 | AE38: 2683 | AF38: 3810 | AG38: 1 | AH38: 14 | AI38: 3 | AJ38: 3 | AK38: 80 | AL38: 0 | AM38: 3 | AN38: 3 | AO38: 3 | AP38: 2 | AQ38: 0 | AR38: 2
A39: No | B39: Travel_Rarely | C39: 35 - 44 | D39: Current Employees | E39: Sales | F39: Marketing | G39: STAFF-49 | H39: 49 | I39: Female | J39: Sales Representative | K39: Married | L39: No | M39: Y | N39: 3 | O39: -2 | P39: 0 | Q39: 35 | R39: 0 | T39: 0 | U39: 1 | V39: 890 | W39: 2 | X39: Bachelor's Degree | Y39: 1 | Z39: 4 | AA39: 97 | AB39: 3 | AC39: 1 | AD39: 4 | AE39: 2014 | AF39: 9687 | AG39: 1 | AH39: 13 | AI39: 3 | AJ39: 1 | AK39: 80 | AL39: 0 | AM39: 2 | AN39: 3 | AO39: 2 | AP39: 2 | AQ39: 2 | AR39: 2
A40: No | B40: Travel_Rarely | C40: 35 - 44 | D40: Current Employees | E40: R&D | F40: Life Sciences | G40: STAFF-51 | H40: 51 | I40: Female | J40: Research Scientist | K40: Married | L40: Yes | M40: Y | N40: 3 | O40: -2 | P40: 0 | Q40: 36 | R40: 0 | T40: 0 | U40: 1 | V40: 852 | W40: 5 | X40: Master's Degree | Y40: 1 | Z40: 2 | AA40: 82 | AB40: 2 | AC40: 1 | AD40: 2 | AE40: 3419 | AF40: 13072 | AG40: 9 | AH40: 14 | AI40: 3 | AJ40: 4 | AK40: 80 | AL40: 1 | AM40: 6 | AN40: 4 | AO40: 1 | AP40: 1 | AQ40: 0 | AR40: 0
...

Sheet Images

Sheet Background 1

Sheet Background 2

Sheet Background 3

Sheet Dashboard

Sheet EmployeeLookup
A1: Employee Lookup (type an Employee Number in B2)
A2: Employee Number | B2: 4
A3: Department | B3: =INDEX(Data!$E$2:$E$1471,MATCH($B$2,Data!$H$2:$H$1471,0)) -> R&D
A4: Job Role | B4: =INDEX(Data!$J$2:$J$1471,MATCH($B$2,Data!$H$2:$H$1471,0)) -> Laboratory Technician
A5: Attrition (Yes/No) | B5: =INDEX(Data!$A$2:$A$1471,MATCH($B$2,Data!$H$2:$H$1471,0)) -> Yes
A6: Monthly Income | B6: =INDEX(Data!$AE$2:$AE$1471,MATCH($B$2,Data!$H$2:$H$1471,0)) -> 2090
A7: Years At Company | B7: =INDEX(Data!$AO$2:$AO$1471,MATCH($B$2,Data!$H$2:$H$1471,0)) -> 0
A8: Dept Attrition Rate (Benchmark) | B8: =INDEX($D$11:$D$13,MATCH(B3,$A$11:$A$13,0)) -> 0.1383975
A10: Department | B10: Headcount | C10: Attrition Count | D10: Attrition Rate
A11: HR | B11: =COUNTIF(Data!$E$2:$E$1471,A11) -> 63 | C11: =SUMIFS(Data!$R$2:$R$1471,Data!$E$2:$E$1471,A11) -> 12 | D11: =C11/B11 -> 0.19047619
A12: R&D | B12: =COUNTIF(Data!$E$2:$E$1471,A12) -> 961 | C12: =SUMIFS(Data!$R$2:$R$1471,Data!$E$2:$E$1471,A12) -> 133 | D12: =C12/B12 -> 0.1383975
A13: Sales | B13: =COUNTIF(Data!$E$2:$E$1471,A13) -> 446 | C13: =SUMIFS(Data!$R$2:$R$1471,Data!$E$2:$E$1471,A13) -> 92 | D13: =C13/B13 -> 0.20627803
A14: Grand Total | B14: =SUM(B11:B13) -> 1470 | C14: =SUM(C11:C13) -> 237 | D14: =C14/B14 -> 0.16122449
